Workbook

Sheet Dashboard
A1: TrendKart Fashion Pvt. Ltd. — Business Analytics Dashboard
A2: Data period: Apr 2024 - Mar 2025 | All figures in Rs. | KPIs and tables are live formulas driven off the cleaned Sales_Transactions sheet
A4: Total Revenue (Rs.) | D4: Total Profit (Rs.) | G4: Profit Margin % | J4: Valid Transactions | M4: Return Rate %
A5: =SUMIF(Sales_Transactions!$R$2:$R$3001,"<>Void/Cancelled",Sales_Transactions!$M$2:$M$3001) -> 9227180 | D5: =SUMIF(Sales_Transactions!$R$2:$R$3001,"<>Void/Cancelled",Sales_Transactions!$O$2:$O$3001) -> 1801437.1 | G5: =D5/A5 -> 0.1952316 | J5: =COUNTIF(Sales_Transactions!$R$2:$R$3001,"<>Void/Cancelled") -> 2948 | M5: =COUNTIF(Sales_Transactions!$R$2:$R$3001,"Returned")/COUNTIF(Sales_Transactions!$R$2:$R$3001,"<>Void/Cancelled") -> 0.047829037
A7: 1. SALES PERFORMANCE — Revenue, Profit & Return Rate by Category
A8: Category | B8: Revenue (Rs.) | C8: Profit (Rs.) | D8: Margin % | E8: Return Rate %
A9: Women Sarees | B9: =SUMIFS(Sales_Transactions!$M$2:$M$3001,Sales_Transactions!$V$2:$V$3001,$A9,Sales_Transactions!$R$2:$R$3001,"<>Void/Cancelled") -> 1103017.8 | C9: =SUMIFS(Sales_Transactions!$O$2:$O$3001,Sales_Transactions!$V$2:$V$3001,$A9,Sales_Transactions!$R$2:$R$3001,"<>Void/Cancelled") -> 202347.57 | D9: =IFERROR(C9/B9,0) -> 0.18344905 | E9: =IFERROR(COUNTIFS(Sales_Transactions!$V$2:$V$3001,$A9,Sales_Transactions!$R$2:$R$3001,"Returned")/COUNTIFS(Sales_Transactions!$V$2:$V$3001,$A9,Sales_Transactions!$R$2:$R$3001,"<>Void/Cancelled"),0) -> 0.021857923
A10: Handbags | B10: =SUMIFS(Sales_Transactions!$M$2:$M$3001,Sales_Transactions!$V$2:$V$3001,$A10,Sales_Transactions!$R$2:$R$3001,"<>Void/Cancelled") -> 994021.98 | C10: =SUMIFS(Sales_Transactions!$O$2:$O$3001,Sales_Transactions!$V$2:$V$3001,$A10,Sales_Transactions!$R$2:$R$3001,"<>Void/Cancelled") -> 213659 | D10: =IFERROR(C10/B10,0) -> 0.21494394 | E10: =IFERROR(COUNTIFS(Sales_Transactions!$V$2:$V$3001,$A10,Sales_Transactions!$R$2:$R$3001,"Returned")/COUNTIFS(Sales_Transactions!$V$2:$V$3001,$A10,Sales_Transactions!$R$2:$R$3001,"<>Void/Cancelled"),0) -> 0.27227723
A11: Watches | B11: =SUMIFS(Sales_Transactions!$M$2:$M$3001,Sales_Transactions!$V$2:$V$3001,$A11,Sales_Transactions!$R$2:$R$3001,"<>Void/Cancelled") -> 937502.18 | C11: =SUMIFS(Sales_Transactions!$O$2:$O$3001,Sales_Transactions!$V$2:$V$3001,$A11,Sales_Transactions!$R$2:$R$3001,"<>Void/Cancelled") -> 181304.56 | D11: =IFERROR(C11/B11,0) -> 0.19339108 | E11: =IFERROR(COUNTIFS(Sales_Transactions!$V$2:$V$3001,$A11,Sales_Transactions!$R$2:$R$3001,"Returned")/COUNTIFS(Sales_Transactions!$V$2:$V$3001,$A11,Sales_Transactions!$R$2:$R$3001,"<>Void/Cancelled"),0) -> 0.032520325
A12: Jewellery | B12: =SUMIFS(Sales_Transactions!$M$2:$M$3001,Sales_Transactions!$V$2:$V$3001,$A12,Sales_Transactions!$R$2:$R$3001,"<>Void/Cancelled") -> 850930.2 | C12: =SUMIFS(Sales_Transactions!$O$2:$O$3001,Sales_Transactions!$V$2:$V$3001,$A12,Sales_Transactions!$R$2:$R$3001,"<>Void/Cancelled") -> 150422.21 | D12: =IFERROR(C12/B12,0) -> 0.17677385 | E12: =IFERROR(COUNTIFS(Sales_Transactions!$V$2:$V$3001,$A12,Sales_Transactions!$R$2:$R$3001,"Returned")/COUNTIFS(Sales_Transactions!$V$2:$V$3001,$A12,Sales_Transactions!$R$2:$R$3001,"<>Void/Cancelled"),0) -> 0.047619048
A13: Women Dresses | B13: =SUMIFS(Sales_Transactions!$M$2:$M$3001,Sales_Transactions!$V$2:$V$3001,$A13,Sales_Transactions!$R$2:$R$3001,"<>Void/Cancelled") -> 648333.43 | C13: =SUMIFS(Sales_Transactions!$O$2:$O$3001,Sales_Transactions!$V$2:$V$3001,$A13,Sales_Transactions!$R$2:$R$3001,"<>Void/Cancelled") -> 108303.11 | D13: =IFERROR(C13/B13,0) -> 0.16704847 | E13: =IFERROR(COUNTIFS(Sales_Transactions!$V$2:$V$3001,$A13,Sales_Transactions!$R$2:$R$3001,"Returned")/COUNTIFS(Sales_Transactions!$V$2:$V$3001,$A13,Sales_Transactions!$R$2:$R$3001,"<>Void/Cancelled"),0) -> 0.03930131
A14: Footwear | B14: =SUMIFS(Sales_Transactions!$M$2:$M$3001,Sales_Transactions!$V$2:$V$3001,$A14,Sales_Transactions!$R$2:$R$3001,"<>Void/Cancelled") -> 521388.97 | C14: =SUMIFS(Sales_Transactions!$O$2:$O$3001,Sales_Transactions!$V$2:$V$3001,$A14,Sales_Transactions!$R$2:$R$3001,"<>Void/Cancelled") -> 89384.64 | D14: =IFERROR(C14/B14,0) -> 0.17143562 | E14: =IFERROR(COUNTIFS(Sales_Transactions!$V$2:$V$3001,$A14,Sales_Transactions!$R$2:$R$3001,"Returned")/COUNTIFS(Sales_Transactions!$V$2:$V$3001,$A14,Sales_Transactions!$R$2:$R$3001,"<>Void/Cancelled"),0) -> 0.028037383
A15: Men Ethnic | B15: =SUMIFS(Sales_Transactions!$M$2:$M$3001,Sales_Transactions!$V$2:$V$3001,$A15,Sales_Transactions!$R$2:$R$3001,"<>Void/Cancelled") -> 508021.06 | C15: =SUMIFS(Sales_Transactions!$O$2:$O$3001,Sales_Transactions!$V$2:$V$3001,$A15,Sales_Transactions!$R$2:$R$3001,"<>Void/Cancelled") -> 96328.01 | D15: =IFERROR(C15/B15,0) -> 0.18961421 | E15: =IFERROR(COUNTIFS(Sales_Transactions!$V$2:$V$3001,$A15,Sales_Transactions!$R$2:$R$3001,"Returned")/COUNTIFS(Sales_Transactions!$V$2:$V$3001,$A15,Sales_Transactions!$R$2:$R$3001,"<>Void/Cancelled"),0) -> 0.029126214
A16: Women Jeans | B16: =SUMIFS(Sales_Transactions!$M$2:$M$3001,Sales_Transactions!$V$2:$V$3001,$A16,Sales_Transactions!$R$2:$R$3001,"<>Void/Cancelled") -> 504452.21 | C16: =SUMIFS(Sales_Transactions!$O$2:$O$3001,Sales_Transactions!$V$2:$V$3001,$A16,Sales_Transactions!$R$2:$R$3001,"<>Void/Cancelled") -> 92155.45 | D16: =IFERROR(C16/B16,0) -> 0.1826842 | E16: =IFERROR(COUNTIFS(Sales_Transactions!$V$2:$V$3001,$A16,Sales_Transactions!$R$2:$R$3001,"Returned")/COUNTIFS(Sales_Transactions!$V$2:$V$3001,$A16,Sales_Transactions!$R$2:$R$3001,"<>Void/Cancelled"),0) -> 0.014150943
A17: Women Kurtis | B17: =SUMIFS(Sales_Transactions!$M$2:$M$3001,Sales_Transactions!$V$2:$V$3001,$A17,Sales_Transactions!$R$2:$R$3001,"<>Void/Cancelled") -> 408431.14 | C17: =SUMIFS(Sales_Transactions!$O$2:$O$3001,Sales_Transactions!$V$2:$V$3001,$A17,Sales_Transactions!$R$2:$R$3001,"<>Void/Cancelled") -> 82676.47 | D17: =IFERROR(C17/B17,0) -> 0.2024245 | E17: =IFERROR(COUNTIFS(Sales_Transactions!$V$2:$V$3001,$A17,Sales_Transactions!$R$2:$R$3001,"Returned")/COUNTIFS(Sales_Transactions!$V$2:$V$3001,$A17,Sales_Transactions!$R$2:$R$3001,"<>Void/Cancelled"),0) -> 0.01793722
A18: Winter Wear | B18: =SUMIFS(Sales_Transactions!$M$2:$M$3001,Sales_Transactions!$V$2:$V$3001,$A18,Sales_Transactions!$R$2:$R$3001,"<>Void/Cancelled") -> 390745.41 | C18: =SUMIFS(Sales_Transactions!$O$2:$O$3001,Sales_Transactions!$V$2:$V$3001,$A18,Sales_Transactions!$R$2:$R$3001,"<>Void/Cancelled") -> 82000.54 | D18: =IFERROR(C18/B18,0) -> 0.20985669 | E18: =IFERROR(COUNTIFS(Sales_Transactions!$V$2:$V$3001,$A18,Sales_Transactions!$R$2:$R$3001,"Returned")/COUNTIFS(Sales_Transactions!$V$2:$V$3001,$A18,Sales_Transactions!$R$2:$R$3001,"<>Void/Cancelled"),0) -> 0.044642857
A19: Women Tops | B19: =SUMIFS(Sales_Transactions!$M$2:$M$3001,Sales_Transactions!$V$2:$V$3001,$A19,Sales_Transactions!$R$2:$R$3001,"<>Void/Cancelled") -> 313703.63 | C19: =SUMIFS(Sales_Transactions!$O$2:$O$3001,Sales_Transactions!$V$2:$V$3001,$A19,Sales_Transactions!$R$2:$R$3001,"<>Void/Cancelled") -> 64627.61 | D19: =IFERROR(C19/B19,0) -> 0.20601486 | E19: =IFERROR(COUNTIFS(Sales_Transactions!$V$2:$V$3001,$A19,Sales_Transactions!$R$2:$R$3001,"Returned")/COUNTIFS(Sales_Transactions!$V$2:$V$3001,$A19,Sales_Transactions!$R$2:$R$3001,"<>Void/Cancelled"),0) -> 0.04784689
A20: Men T-Shirts | B20: =SUMIFS(Sales_Transactions!$M$2:$M$3001,Sales_Transactions!$V$2:$V$3001,$A20,Sales_Transactions!$R$2:$R$3001,"<>Void/Cancelled") -> 312534.72 | C20: =SUMIFS(Sales_Transactions!$O$2:$O$3001,Sales_Transactions!$V$2:$V$3001,$A20,Sales_Transactions!$R$2:$R$3001,"<>Void/Cancelled") -> 94494.79 | D20: =IFERROR(C20/B20,0) -> 0.30234974 | E20: =IFERROR(COUNTIFS(Sales_Transactions!$V$2:$V$3001,$A20,Sales_Transactions!$R$2:$R$3001,"Returned")/COUNTIFS(Sales_Transactions!$V$2:$V$3001,$A20,Sales_Transactions!$R$2:$R$3001,"<>Void/Cancelled"),0) -> 0.035714286
... A29: Unknown | B29: =SUMIFS(Sales_Transactions!$M$2:$M$3001,Sales_Transactions!$V$2:$V$3001,$A29,Sales_Transactions!$R$2:$R$3001,"<>Void/Cancelled") -> 17218.58 | C29: =SUMIFS(Sales_Transactions!$O$2:$O$3001,Sales_Transactions!$V$2:$V$3001,$A29,Sales_Transactions!$R$2:$R$3001,"<>Void/Cancelled") -> 5105.73 | D29: =IFERROR(C29/B29,0) -> 0.29652445 | E29: =IFERROR(COUNTIFS(Sales_Transactions!$V$2:$V$3001,$A29,Sales_Transactions!$R$2:$R$3001,"Returned")/COUNTIFS(Sales_Transactions!$V$2:$V$3001,$A29,Sales_Transactions!$R$2:$R$3001,"<>Void/Cancelled"),0) -> 0
A31: 2. CUSTOMER BEHAVIOUR — Revenue by Region & Membership Tier
A32: Region | B32: Revenue (Rs.) | C32: Txns | D32: Avg Order Value | F32: Membership | G32: Revenue (Rs.) | H32: Txns | I32: Avg Order Value
A33: South Zone 1 | B33: =SUMIFS(Sales_Transactions!$M$2:$M$3001,Sales_Transactions!$Y$2:$Y$3001,$A33,Sales_Transactions!$R$2:$R$3001,"<>Void/Cancelled") -> 4463451.9 | C33: =COUNTIFS(Sales_Transactions!$Y$2:$Y$3001,$A33,Sales_Transactions!$R$2:$R$3001,"<>Void/Cancelled") -> 1449 | D33: =IFERROR(B33/C33,0) -> 3080.3671 | F33: Gold | G33: =SUMIFS(Sales_Transactions!$M$2:$M$3001,Sales_Transactions!$Z$2:$Z$3001,$F33,Sales_Transactions!$R$2:$R$3001,"<>Void/Cancelled") -> 2558088.3 | H33: =COUNTIFS(Sales_Transactions!$Z$2:$Z$3001,$F33,Sales_Transactions!$R$2:$R$3001,"<>Void/Cancelled") -> 669 | I33: =IFERROR(G33/H33,0) -> 3823.7494
A34: South Zone 2 | B34: =SUMIFS(Sales_Transactions!$M$2:$M$3001,Sales_Transactions!$Y$2:$Y$3001,$A34,Sales_Transactions!$R$2:$R$3001,"<>Void/Cancelled") -> 2554815.9 | C34: =COUNTIFS(Sales_Transactions!$Y$2:$Y$3001,$A34,Sales_Transactions!$R$2:$R$3001,"<>Void/Cancelled") -> 792 | D34: =IFERROR(B34/C34,0) -> 3225.7777 | F34: Platinum | G34: =SUMIFS(Sales_Transactions!$M$2:$M$3001,Sales_Transactions!$Z$2:$Z$3001,$F34,Sales_Transactions!$R$2:$R$3001,"<>Void/Cancelled") -> 806954.82 | H34: =COUNTIFS(Sales_Transactions!$Z$2:$Z$3001,$F34,Sales_Transactions!$R$2:$R$3001,"<>Void/Cancelled") -> 289 | I34: =IFERROR(G34/H34,0) -> 2792.2312
A35: South Zone 3 | B35: =SUMIFS(Sales_Transactions!$M$2:$M$3001,Sales_Transactions!$Y$2:$Y$3001,$A35,Sales_Transactions!$R$2:$R$3001,"<>Void/Cancelled") -> 2208912.1 | C35: =COUNTIFS(Sales_Transactions!$Y$2:$Y$3001,$A35,Sales_Transactions!$R$2:$R$3001,"<>Void/Cancelled") -> 707 | D35: =IFERROR(B35/C35,0) -> 3124.3453 | F35: Silver | G35: =SUMIFS(Sales_Transactions!$M$2:$M$3001,Sales_Transactions!$Z$2:$Z$3001,$F35,Sales_Transactions!$R$2:$R$3001,"<>Void/Cancelled") -> 2863695.1 | H35: =COUNTIFS(Sales_Transactions!$Z$2:$Z$3001,$F35,Sales_Transactions!$R$2:$R$3001,"<>Void/Cancelled") -> 960 | I35: =IFERROR(G35/H35,0) -> 2983.0157
F36: Regular | G36: =SUMIFS(Sales_Transactions!$M$2:$M$3001,Sales_Transactions!$Z$2:$Z$3001,$F36,Sales_Transactions!$R$2:$R$3001,"<>Void/Cancelled") -> 2973904 | H36: =COUNTIFS(Sales_Transactions!$Z$2:$Z$3001,$F36,Sales_Transactions!$R$2:$R$3001,"<>Void/Cancelled") -> 1024 | I36: =IFERROR(G36/H36,0) -> 2904.2031
A38: 3. SALES TREND & INVENTORY — Monthly Revenue and Product Movement
A39: Month | B39: Revenue (Rs.) | C39: Profit (Rs.) | F39: Fast-Moving (Qty Sold) | G39: Units | I39: Slow-Moving (Qty Sold) | J39: Units
A40: 2024-04 | B40: =SUMIFS(Sales_Transactions!$M$2:$M$3001,Sales_Transactions!$AA$2:$AA$3001,$A40,Sales_Transactions!$R$2:$R$3001,"<>Void/Cancelled") -> 683356.93 | C40: =SUMIFS(Sales_Transactions!$O$2:$O$3001,Sales_Transactions!$AA$2:$AA$3001,$A40,Sales_Transactions!$R$2:$R$3001,"<>Void/Cancelled") -> 131910.18 | F40: PRD0043 - GRT Jewellers Sling Bag Olive | G40: 156 | I40: PRD0008 - Aurelia Zip Wallet Grey | J40: 2
A41: 2024-05 | B41: =SUMIFS(Sales_Transactions!$M$2:$M$3001,Sales_Transactions!$AA$2:$AA$3001,$A41,Sales_Transactions!$R$2:$R$3001,"<>Void/Cancelled") -> 716615.74 | C41: =SUMIFS(Sales_Transactions!$O$2:$O$3001,Sales_Transactions!$AA$2:$AA$3001,$A41,Sales_Transactions!$R$2:$R$3001,"<>Void/Cancelled") -> 143626.61 | F41: PRD0236 - Reebok Graphic Tee Cream | G41: 69 | I41: PRD0162 - Skechers Formal Trouser Brown | J41: 3
A42: 2024-06 | B42: =SUMIFS(Sales_Transactions!$M$2:$M$3001,Sales_Transactions!$AA$2:$AA$3001,$A42,Sales_Transactions!$R$2:$R$3001,"<>Void/Cancelled") -> 705197.67 | C42: =SUMIFS(Sales_Transactions!$O$2:$O$3001,Sales_Transactions!$AA$2:$AA$3001,$A42,Sales_Transactions!$R$2:$R$3001,"<>Void/Cancelled") -> 125032.19 | F42: PRD0134 - Jack & Jones Maxi Dress Maroon | G42: 68 | I42: PRD0185 - Max Fashion Nehru Jacket Purple | J42: 4
A43: 2024-07 | B43: =SUMIFS(Sales_Transactions!$M$2:$M$3001,Sales_Transactions!$AA$2:$AA$3001,$A43,Sales_Transactions!$R$2:$R$3001,"<>Void/Cancelled") -> 575940.09 | C43: =SUMIFS(Sales_Transactions!$O$2:$O$3001,Sales_Transactions!$AA$2:$AA$3001,$A43,Sales_Transactions!$R$2:$R$3001,"<>Void/Cancelled") -> 110065.95 | F43: PRD0142 - Global Desi Round Neck Green | G43: 64 | I43: PRD0249 - Titan Track Pant Wine | J43: 4
A44: 2024-08 | B44: =SUMIFS(Sales_Transactions!$M$2:$M$3001,Sales_Transactions!$AA$2:$AA$3001,$A44,Sales_Transactions!$R$2:$R$3001,"<>Void/Cancelled") -> 624765.64 | C44: =SUMIFS(Sales_Transactions!$O$2:$O$3001,Sales_Transactions!$AA$2:$AA$3001,$A44,Sales_Transactions!$R$2:$R$3001,"<>Void/Cancelled") -> 122773.23 | F44: PRD0140 - Metro Shoes Polo Purple | G44: 62 | I44: PRD0206 - Numero Uno Track Pant White | J44: 4
A45: 2024-09 | B45: =SUMIFS(Sales_Transactions!$M$2:$M$3001,Sales_Transactions!$AA$2:$AA$3001,$A45,Sales_Transactions!$R$2:$R$3001,"<>Void/Cancelled") -> 842808.66 | C45: =SUMIFS(Sales_Transactions!$O$2:$O$3001,Sales_Transactions!$AA$2:$AA$3001,$A45,Sales_Transactions!$R$2:$R$3001,"<>Void/Cancelled") -> 177387.37 | F45: PRD0117 - Nike Shirt Dress Peach | G45: 61 | I45: PRD0024 - Spykar Backpack Peach | J45: 5
A46: 2024-10 | B46: =SUMIFS(Sales_Transactions!$M$2:$M$3001,Sales_Transactions!$AA$2:$AA$3001,$A46,Sales_Transactions!$R$2:$R$3001,"<>Void/Cancelled") -> 1519147.1 | C46: =SUMIFS(Sales_Transactions!$O$2:$O$3001,Sales_Transactions!$AA$2:$AA$3001,$A46,Sales_Transactions!$R$2:$R$3001,"<>Void/Cancelled") -> 301165.34 | F46: PRD0137 - Peter England Crop Top Green | G46: 56 | I46: PRD0166 - Global Desi Joggers Charcoal | J46: 5
A47: 2024-11 | B47: =SUMIFS(Sales_Transactions!$M$2:$M$3001,Sales_Transactions!$AA$2:$AA$3001,$A47,Sales_Transactions!$R$2:$R$3001,"<>Void/Cancelled") -> 1054251.4 | C47: =SUMIFS(Sales_Transactions!$O$2:$O$3001,Sales_Transactions!$AA$2:$AA$3001,$A47,Sales_Transactions!$R$2:$R$3001,"<>Void/Cancelled") -> 194655.84 | F47: PRD0130 - Spykar Cotton Saree Black | G47: 56 | I47: PRD0104 - GRT Jewellers Chinos Purple | J47: 6
A48: 2024-12 | B48: =SUMIFS(Sales_Transactions!$M$2:$M$3001,Sales_Transactions!$AA$2:$AA$3001,$A48,Sales_Transactions!$R$2:$R$3001,"<>Void/Cancelled") -> 891356.08 | C48: =SUMIFS(Sales_Transactions!$O$2:$O$3001,Sales_Transactions!$AA$2:$AA$3001,$A48,Sales_Transactions!$R$2:$R$3001,"<>Void/Cancelled") -> 180854.07
A49: 2025-01 | B49: =SUMIFS(Sales_Transactions!$M$2:$M$3001,Sales_Transactions!$AA$2:$AA$3001,$A49,Sales_Transactions!$R$2:$R$3001,"<>Void/Cancelled") -> 305174.24 | C49: =SUMIFS(Sales_Transactions!$O$2:$O$3001,Sales_Transactions!$AA$2:$AA$3001,$A49,Sales_Transactions!$R$2:$R$3001,"<>Void/Cancelled") -> 54860.77
A50: 2025-02 | B50: =SUMIFS(Sales_Transactions!$M$2:$M$3001,Sales_Transactions!$AA$2:$AA$3001,$A50,Sales_Transactions!$R$2:$R$3001,"<>Void/Cancelled") -> 655012.42 | C50: =SUMIFS(Sales_Transactions!$O$2:$O$3001,Sales_Transactions!$AA$2:$AA$3001,$A50,Sales_Transactions!$R$2:$R$3001,"<>Void/Cancelled") -> 118923.49
A51: 2025-03 | B51: =SUMIFS(Sales_Transactions!$M$2:$M$3001,Sales_Transactions!$AA$2:$AA$3001,$A51,Sales_Transactions!$R$2:$R$3001,"<>Void/Cancelled") -> 653554.07 | C51: =SUMIFS(Sales_Transactions!$O$2:$O$3001,Sales_Transactions!$AA$2:$AA$3001,$A51,Sales_Transactions!$R$2:$R$3001,"<>Void/Cancelled") -> 140182.08
A53: 4. STORE OPERATIONS — Top & Bottom Performing Stores by Revenue
...

Sheet Sales_Transactions
A1: Invoice No | B1: Invoice Date | C1: Customer_ID | D1: Product_ID | E1: Store_ID | F1: Employee_ID | G1: Quantity | H1: Unit Price | I1: Discount % | J1: Discount Amount | K1: GST % | L1: GST Amount | M1: Sales Amount | N1: Cost Amount | O1: Profit | P1: Payment Mode | Q1: Sales Channel | R1: Return Status | S1: Order Time | T1: Day Type | U1: Loss_Making_Flag | V1: Category | W1: Brand | X1: Store Name | Y1: Region | Z1: Membership | AA1: Month | AB1: Supplier_ID
A2: INV100001 | B2: 45642 | C2: CUST0052 | D2: PRD0200 | E2: STR037 | F2: EMP0276 | G2: 1 | H2: 749.84 | I2: 10 | J2: 74.98 | K2: 5 | L2: 33.74 | M2: 708.6 | N2: 496.67 | O2: 178.19 | P2: UPI | Q2: Offline | R2: Not Returned | S2: 18:16 | T2: Weekday | U2: No | V2: =IFERROR(INDEX(Products!$C:$C,MATCH(D2,Products!$A:$A,0)),"Unknown") -> Women Kurtis | W2: =IFERROR(INDEX(Products!$E:$E,MATCH(D2,Products!$A:$A,0)),"Unknown") -> Pepe Jeans | X2: =IFERROR(INDEX(Stores!$B:$B,MATCH(E2,Stores!$A:$A,0)),"Unknown") -> TrendMart Vijayawada High Street | Y2: =IFERROR(INDEX(Stores!$E:$E,MATCH(E2,Stores!$A:$A,0)),"Unknown") -> South Zone 3 | Z2: =IFERROR(INDEX(Customers!$J:$J,MATCH(C2,Customers!$A:$A,0)),"Unknown") -> Regular | AA2: =TEXT(B2,"YYYY-MM") -> 2024-12 | AB2: =IFERROR(INDEX(Products!$I:$I,MATCH(D2,Products!$A:$A,0)),"Unknown") -> SUP049
A3: INV100002 | B3: 45578 | C3: CUST0463 | D3: PRD0245 | E3: STR102 | F3: EMP0156 | G3: 2 | H3: 909.55 | I3: 25 | J3: 454.77 | K3: 5 | L3: 68.22 | M3: 1432.55 | N3: 984.22 | O3: 380.11 | P3: Debit Card | Q3: Online | R3: Not Returned | S3: 13:25 | T3: Weekend | U3: No | V3: =IFERROR(INDEX(Products!$C:$C,MATCH(D3,Products!$A:$A,0)),"Unknown") -> Men T-Shirts | W3: =IFERROR(INDEX(Products!$E:$E,MATCH(D3,Products!$A:$A,0)),"Unknown") -> Reebok | X3: =IFERROR(INDEX(Stores!$B:$B,MATCH(E3,Stores!$A:$A,0)),"Unknown") -> TrendMart Tirunelveli High Street | Y3: =IFERROR(INDEX(Stores!$E:$E,MATCH(E3,Stores!$A:$A,0)),"Unknown") -> South Zone 1 | Z3: =IFERROR(INDEX(Customers!$J:$J,MATCH(C3,Customers!$A:$A,0)),"Unknown") -> Regular | AA3: =TEXT(B3,"YYYY-MM") -> 2024-10 | AB3: =IFERROR(INDEX(Products!$I:$I,MATCH(D3,Products!$A:$A,0)),"Unknown") -> SUP073
A4: INV100003 | B4: 45657 | C4: CUST0711 | D4: PRD0065 | E4: STR011 | F4: EMP0223 | G4: 2 | H4: 3872.21 | I4: 0 | J4: 0 | K4: 12 | L4: 929.33 | M4: 8673.75 | N4: 5267.12 | O4: 2477.3 | P4: Debit Card | Q4: Online | R4: Not Returned | S4: 21:10 | T4: Weekday | U4: No | V4: =IFERROR(INDEX(Products!$C:$C,MATCH(D4,Products!$A:$A,0)),"Unknown") -> Women Sarees | W4: =IFERROR(INDEX(Products!$E:$E,MATCH(D4,Products!$A:$A,0)),"Unknown") -> Westside | X4: =IFERROR(INDEX(Stores!$B:$B,MATCH(E4,Stores!$A:$A,0)),"Unknown") -> TrendMart Tirupati Standard | Y4: =IFERROR(INDEX(Stores!$E:$E,MATCH(E4,Stores!$A:$A,0)),"Unknown") -> South Zone 3 | Z4: =IFERROR(INDEX(Customers!$J:$J,MATCH(C4,Customers!$A:$A,0)),"Unknown") -> Silver | AA4: =TEXT(B4,"YYYY-MM") -> 2024-12 | AB4: =IFERROR(INDEX(Products!$I:$I,MATCH(D4,Products!$A:$A,0)),"Unknown") -> SUP069
A5: INV100004 | B5: 45437 | C5: CUST0466 | D5: PRD0224 | E5: STR078 | F5: EMP0170 | G5: 4 | H5: 4857.75 | I5: 20 | J5: 3886.2 | K5: 12 | L5: 1865.38 | M5: 17410.18 | N5: 13483.2 | O5: 2061.6 | P5: UPI | Q5: Online | R5: Not Returned | S5: 13:45 | T5: Weekend | U5: No | V5: =IFERROR(INDEX(Products!$C:$C,MATCH(D5,Products!$A:$A,0)),"Unknown") -> Women Sarees | W5: =IFERROR(INDEX(Products!$E:$E,MATCH(D5,Products!$A:$A,0)),"Unknown") -> Max Fashion | X5: =IFERROR(INDEX(Stores!$B:$B,MATCH(E5,Stores!$A:$A,0)),"Unknown") -> TrendMart Vellore Standard | Y5: =IFERROR(INDEX(Stores!$E:$E,MATCH(E5,Stores!$A:$A,0)),"Unknown") -> South Zone 1 | Z5: =IFERROR(INDEX(Customers!$J:$J,MATCH(C5,Customers!$A:$A,0)),"Unknown") -> Regular | AA5: =TEXT(B5,"YYYY-MM") -> 2024-05 | AB5: =IFERROR(INDEX(Products!$I:$I,MATCH(D5,Products!$A:$A,0)),"Unknown") -> SUP084
A6: INV100005 | B6: 45487 | C6: CUST0406 | D6: PRD0035 | E6: STR058 | F6: EMP0090 | G6: 1 | H6: 874.25 | I6: 0 | J6: 0 | K6: 5 | L6: 43.71 | M6: 917.96 | N6: 539.76 | O6: 334.49 | P6: Credit Card | Q6: Offline | R6: Not Returned | S6: 21:11 | T6: Weekend | U6: No | V6: =IFERROR(INDEX(Products!$C:$C,MATCH(D6,Products!$A:$A,0)),"Unknown") -> Women Kurtis | W6: =IFERROR(INDEX(Products!$E:$E,MATCH(D6,Products!$A:$A,0)),"Unknown") -> Reebok | X6: =IFERROR(INDEX(Stores!$B:$B,MATCH(E6,Stores!$A:$A,0)),"Unknown") -> TrendMart Thoothukudi Flagship | Y6: =IFERROR(INDEX(Stores!$E:$E,MATCH(E6,Stores!$A:$A,0)),"Unknown") -> South Zone 1 | Z6: =IFERROR(INDEX(Customers!$J:$J,MATCH(C6,Customers!$A:$A,0)),"Unknown") -> Regular | AA6: =TEXT(B6,"YYYY-MM") -> 2024-07 | AB6: =IFERROR(INDEX(Products!$I:$I,MATCH(D6,Products!$A:$A,0)),"Unknown") -> SUP012
A7: INV100006 | B7: 45704 | C7: CUST0084 | D7: PRD0199 | E7: STR074 | F7: EMP0204 | G7: 2 | H7: 3390.61 | I7: 30 | J7: 2034.37 | K7: 12 | L7: 569.62 | M7: 5316.47 | N7: 4849.24 | O7: -102.39 | P7: Credit Card | Q7: Offline | R7: Not Returned | S7: 10:24 | T7: Weekend | U7: Yes | V7: =IFERROR(INDEX(Products!$C:$C,MATCH(D7,Products!$A:$A,0)),"Unknown") -> Footwear | W7: =IFERROR(INDEX(Products!$E:$E,MATCH(D7,Products!$A:$A,0)),"Unknown") -> US Polo Assn | X7: =IFERROR(INDEX(Stores!$B:$B,MATCH(E7,Stores!$A:$A,0)),"Unknown") -> TrendMart Kurnool High Street | Y7: =IFERROR(INDEX(Stores!$E:$E,MATCH(E7,Stores!$A:$A,0)),"Unknown") -> South Zone 3 | Z7: =IFERROR(INDEX(Customers!$J:$J,MATCH(C7,Customers!$A:$A,0)),"Unknown") -> Platinum | AA7: =TEXT(B7,"YYYY-MM") -> 2025-02 | AB7: =IFERROR(INDEX(Products!$I:$I,MATCH(D7,Products!$A:$A,0)),"Unknown") -> SUP084
A8: INV100007 | B8: 45457 | C8: CUST0714 | D8: PRD0040 | E8: STR062 | F8: EMP0215 | G8: 4 | H8: 1474.99 | I8: 0 | J8: 0 | K8: 12 | L8: 708 | M8: 6607.96 | N8: 4594.64 | O8: 1305.32 | P8: Cash | Q8: Offline | R8: Not Returned | S8: 20:20 | T8: Weekday | U8: No | V8: =IFERROR(INDEX(Products!$C:$C,MATCH(D8,Products!$A:$A,0)),"Unknown") -> Sportswear | W8: =IFERROR(INDEX(Products!$E:$E,MATCH(D8,Products!$A:$A,0)),"Unknown") -> US Polo Assn | X8: =IFERROR(INDEX(Stores!$B:$B,MATCH(E8,Stores!$A:$A,0)),"Unknown") -> TrendMart Vijayawada Standard | Y8: =IFERROR(INDEX(Stores!$E:$E,MATCH(E8,Stores!$A:$A,0)),"Unknown") -> South Zone 3 | Z8: =IFERROR(INDEX(Customers!$J:$J,MATCH(C8,Customers!$A:$A,0)),"Unknown") -> Silver | AA8: =TEXT(B8,"YYYY-MM") -> 2024-06 | AB8: =IFERROR(INDEX(Products!$I:$I,MATCH(D8,Products!$A:$A,0)),"Unknown") -> SUP043
A9: INV100008 | B9: 45678 | C9: CUST0121 | D9: PRD0196 | E9: STR084 | F9: EMP0285 | G9: 1 | H9: 1407.12 | I9: 0 | J9: 0 | K9: 12 | L9: 168.85 | M9: 1575.97 | N9: 1067.72 | O9: 339.4 | P9: UPI | Q9: Offline | R9: Not Returned | S9: 21:28 | T9: Weekday | U9: No | V9: =IFERROR(INDEX(Products!$C:$C,MATCH(D9,Products!$A:$A,0)),"Unknown") -> Men Jeans | W9: =IFERROR(INDEX(Products!$E:$E,MATCH(D9,Products!$A:$A,0)),"Unknown") -> Metro Shoes | X9: =IFERROR(INDEX(Stores!$B:$B,MATCH(E9,Stores!$A:$A,0)),"Unknown") -> TrendMart Tirupati High Street | Y9: =IFERROR(INDEX(Stores!$E:$E,MATCH(E9,Stores!$A:$A,0)),"Unknown") -> South Zone 3 | Z9: =IFERROR(INDEX(Customers!$J:$J,MATCH(C9,Customers!$A:$A,0)),"Unknown") -> Silver | AA9: =TEXT(B9,"YYYY-MM") -> 2025-01 | AB9: =IFERROR(INDEX(Products!$I:$I,MATCH(D9,Products!$A:$A,0)),"Unknown") -> SUP059
A10: INV100009 | B10: 45541 | C10: CUST0782 | D10: PRD0114 | E10: STR021 | F10: EMP0001 | G10: 5 | H10: 851.61 | I10: 5 | J10: 212.9 | K10: 5 | L10: 202.26 | M10: 4247.41 | N10: 2443 | O10: 1602.15 | P10: Debit Card | Q10: Offline | R10: Not Returned | S10: 19:05 | T10: Weekday | U10: No | V10: =IFERROR(INDEX(Products!$C:$C,MATCH(D10,Products!$A:$A,0)),"Unknown") -> Accessories | W10: =IFERROR(INDEX(Products!$E:$E,MATCH(D10,Products!$A:$A,0)),"Unknown") -> Arrow | X10: =IFERROR(INDEX(Stores!$B:$B,MATCH(E10,Stores!$A:$A,0)),"Unknown") -> TrendMart Kozhikode Standard | Y10: =IFERROR(INDEX(Stores!$E:$E,MATCH(E10,Stores!$A:$A,0)),"Unknown") -> South Zone 1 | Z10: =IFERROR(INDEX(Customers!$J:$J,MATCH(C10,Customers!$A:$A,0)),"Unknown") -> Gold | AA10: =TEXT(B10,"YYYY-MM") -> 2024-09 | AB10: =IFERROR(INDEX(Products!$I:$I,MATCH(D10,Products!$A:$A,0)),"Unknown") -> SUP018
A11: INV100010 | B11: 45583 | C11: CUST0429 | D11: PRD0075 | E11: STR085 | F11: EMP0090 | G11: 1 | H11: 1041.15 | I11: 0 | J11: 0 | K11: 12 | L11: 124.94 | M11: 1166.09 | N11: 692.53 | O11: 348.62 | P11: Credit Card | Q11: Offline | R11: Not Returned | S11: 10:34 | T11: Weekday | U11: No | V11: =IFERROR(INDEX(Products!$C:$C,MATCH(D11,Products!$A:$A,0)),"Unknown") -> Women Jeans | W11: =IFERROR(INDEX(Products!$E:$E,MATCH(D11,Products!$A:$A,0)),"Unknown") -> Sonata | X11: =IFERROR(INDEX(Stores!$B:$B,MATCH(E11,Stores!$A:$A,0)),"Unknown") -> TrendMart Nizamabad Outlet | Y11: =IFERROR(INDEX(Stores!$E:$E,MATCH(E11,Stores!$A:$A,0)),"Unknown") -> South Zone 2 | Z11: =IFERROR(INDEX(Customers!$J:$J,MATCH(C11,Customers!$A:$A,0)),"Unknown") -> Regular | AA11: =TEXT(B11,"YYYY-MM") -> 2024-10 | AB11: =IFERROR(INDEX(Products!$I:$I,MATCH(D11,Products!$A:$A,0)),"Unknown") -> SUP014
A12: INV100011 | B12: 45677 | C12: CUST0162 | D12: PRD0117 | E12: STR004 | F12: EMP0258 | G12: 4 | H12: 1761.12 | I12: 10 | J12: 704.45 | K12: 12 | L12: 760.8 | M12: 7100.83 | N12: 5599.4 | O12: 740.63 | P12: Credit Card | Q12: Offline | R12: Not Returned | S12: 13:20 | T12: Weekday | U12: No | V12: =IFERROR(INDEX(Products!$C:$C,MATCH(D12,Products!$A:$A,0)),"Unknown") -> Women Dresses | W12: =IFERROR(INDEX(Products!$E:$E,MATCH(D12,Products!$A:$A,0)),"Unknown") -> Nike | X12: =IFERROR(INDEX(Stores!$B:$B,MATCH(E12,Stores!$A:$A,0)),"Unknown") -> TrendMart Kalaburagi Mall Kiosk | Y12: =IFERROR(INDEX(Stores!$E:$E,MATCH(E12,Stores!$A:$A,0)),"Unknown") -> South Zone 2 | Z12: =IFERROR(INDEX(Customers!$J:$J,MATCH(C12,Customers!$A:$A,0)),"Unknown") -> Silver | AA12: =TEXT(B12,"YYYY-MM") -> 2025-01 | AB12: =IFERROR(INDEX(Products!$I:$I,MATCH(D12,Products!$A:$A,0)),"Unknown") -> SUP073
A13: INV100012 | B13: 45736 | C13: CUST0794 | D13: PRD0078 | E13: STR068 | F13: EMP0204 | G13: 1 | H13: 1019.42 | I13: 5 | J13: 50.97 | K13: 12 | L13: 116.21 | M13: 1084.66 | N13: 828.44 | O13: 140.01 | P13: UPI | Q13: Online | R13: Not Returned | S13: 18:28 | T13: Weekday | U13: No | V13: =IFERROR(INDEX(Products!$C:$C,MATCH(D13,Products!$A:$A,0)),"Unknown") -> Men Jeans | W13: =IFERROR(INDEX(Products!$E:$E,MATCH(D13,Products!$A:$A,0)),"Unknown") -> Metro Shoes | X13: =IFERROR(INDEX(Stores!$B:$B,MATCH(E13,Stores!$A:$A,0)),"Unknown") -> TrendMart Madurai Mall Kiosk | Y13: =IFERROR(INDEX(Stores!$E:$E,MATCH(E13,Stores!$A:$A,0)),"Unknown") -> South Zone 1 | Z13: =IFERROR(INDEX(Customers!$J:$J,MATCH(C13,Customers!$A:$A,0)),"Unknown") -> Silver | AA13: =TEXT(B13,"YYYY-MM") -> 2025-03 | AB13: =IFERROR(INDEX(Products!$I:$I,MATCH(D13,Products!$A:$A,0)),"Unknown") -> SUP022
... A3001: INV103000 | B3001: 45449 | C3001: CUST0203 | D3001: PRD0154 | E3001: STR069 | F3001: EMP0225 | G3001: 3 | H3001: 630.4 | I3001: 30 | J3001: 567.36 | K3001: 5 | L3001: 66.19 | M3001: 1390.03 | N3001: 1119.81 | O3001: 204.03 | P3001: Debit Card | Q3001: Offline | R3001: Not Returned | S3001: 16:08 | T3001: Weekday | U3001: No | V3001: =IFERROR(INDEX(Products!$C:$C,MATCH(D3001,Products!$A:$A,0)),"Unknown") -> Men T-Shirts | W3001: =IFERROR(INDEX(Products!$E:$E,MATCH(D3001,Products!$A:$A,0)),"Unknown") -> Indian Terrain | X3001: =IFERROR(INDEX(Stores!$B:$B,MATCH(E3001,Stores!$A:$A,0)),"Unknown") -> TrendMart Erode Mall Kiosk | Y3001: =IFERROR(INDEX(Stores!$E:$E,MATCH(E3001,Stores!$A:$A,0)),"Unknown") -> South Zone 1 | Z3001: =IFERROR(INDEX(Customers!$J:$J,MATCH(C3001,Customers!$A:$A,0)),"Unknown") -> Silver | AA3001: =TEXT(B3001,"YYYY-MM") -> 2024-06 | AB3001: =IFERROR(INDEX(Products!$I:$I,MATCH(D3001,Products!$A:$A,0)),"Unknown") -> SUP074

Sheet Customers
A1: Customer_ID | B1: Customer Name | C1: Gender | D1: DOB | E1: Phone | F1: Email | G1: City | H1: State | I1: Region | J1: Membership | K1: Registration Date | L1: Occupation | M1: Duplicate_Phone_Flag | N1: Invalid_Email_Flag
A2: CUST0001 | B2: Yamini Krishnan | C2: Female | D2: 39080 | E2: 9289611223 | F2: yamini.krishnan1@yahoo.com | G2: Belagavi | H2: Karnataka | I2: South Zone 2 | J2: Gold | K2: 44615 | L2: Nurse | M2: No | N2: No
A3: CUST0002 | B3: Vasanthi Subramaniam | C3: Female | D3: 33566 | E3: 9938425304 | F3: vasanthi.subramaniam2@yahoo.com | G3: Tirupati | H3: Andhra Pradesh | I3: South Zone 3 | J3: Silver | K3: 43290 | L3: HR Professional | M3: No | N3: No
A4: CUST0003 | B4: Swathi Bhat | C4: Female | D4: 35659 | E4: 9286857872 | F4: swathi.bhat3@outlook.com | G4: Vellore | H4: Tamil Nadu | I4: South Zone 1 | J4: Regular | K4: 45619 | L4: Business Owner | M4: No | N4: No
A5: CUST0004 | B5: Bindu Varma | C5: Female | D5: 35468 | E5: 9033373634 | F5: bindu.varma4@rediffmail.com | G5: Nellore | H5: Andhra Pradesh | I5: South Zone 3 | J5: Silver | K5: 44743 | L5: Marketing Professional | M5: No | N5: No
A6: CUST0005 | B6: Indira Raman | C6: Female | D6: 27913 | E6: 9785390789 | F6: indira.raman5@outlook.com | G6: Kochi | H6: Kerala | I6: South Zone 1 | J6: Silver | K6: 43445 | L6: Sales Professional | M6: No | N6: No
A7: CUST0006 | B7: Rajesh Gopalakrishnan | C7: Male | D7: 30443 | E7: 9273415148 | F7: rajesh.gopalakrishnan6@hotmail.com | G7: Karimnagar | H7: Telangana | I7: South Zone 2 | J7: Gold | K7: 44667 | L7: Software Engineer | M7: No | N7: No
A8: CUST0007 | B8: Sangeeta Gounder | C8: Female | D8: 38924 | E8: 9835354443 | F8: sangeeta.gounder7@hotmail.com | G8: Mysuru | H8: Karnataka | I8: South Zone 2 | J8: Silver | K8: 44576 | L8: Teacher | M8: No | N8: No
A9: CUST0008 | B9: Deepthi Naicker | C9: Female | D9: 23882 | E9: 9907826333 | F9: deepthi.naicker8@rediffmail.com | G9: Nizamabad | H9: Telangana | I9: South Zone 2 | J9: Regular | K9: 44755 | L9: Architect | M9: No | N9: No
A10: CUST0009 | B10: Rajesh Srinivasan | C10: Male | D10: 29324 | E10: 9377805292 | F10: rajesh.srinivasan9@outlook.com | G10: Tirunelveli | H10: Tamil Nadu | I10: South Zone 1 | J10: Regular | K10: 44857 | L10: Consultant | M10: No | N10: No
A11: CUST0010 | B11: Divya Sharma | C11: Female | D11: 37020 | E11: 9845909022 | F11: divya.sharma10@outlook.com | G11: Nizamabad | H11: Telangana | I11: South Zone 2 | J11: Silver | K11: 44844 | L11: Architect | M11: No | N11: No
A12: CUST0011 | B12: Chandrika Natarajan | C12: Female | D12: 27088 | E12: 9159741218 | F12: chandrika.natarajan11@yahoo.com | G12: Visakhapatnam | H12: Andhra Pradesh | I12: South Zone 3 | J12: Gold | K12: 43872 | L12: Freelancer | M12: No | N12: No
A13: CUST0012 | B13: Anil Iyengar | C13: Male | D13: 26801 | E13: 9334817058 | F13: anil.iyengar12@gmail.com | G13: Mysuru | H13: Karnataka | I13: South Zone 2 | J13: Regular | K13: 44681 | L13: Sales Professional | M13: No | N13: No
... A851: CUST0850 | B851: Chidambaram Krishnan | C851: Male | D851: 33996 | E851: 9164359900 | F851: chidambaram.krishnan850@hotmail.com | G851: Karimnagar | H851: Telangana | I851: South Zone 2 | J851: Regular | K851: 44198 | L851: Bank Employee | M851: No | N851: No

Sheet Products
A1: Product_ID | B1: Product_Name | C1: Category | D1: Subcategory | E1: Brand | F1: Size | G1: Color | H1: Material | I1: Supplier_ID | J1: Cost Price | K1: Selling Price | L1: MRP | M1: Launch Date | N1: Status | O1: Duplicate_Name_Flag
A2: PRD0001 | B2: Mufti Sweater Peach | C2: Winter Wear | D2: Sweater | E2: Mufti | F2: S | G2: Peach | H2: Khadi | I2: SUP078 | J2: 1409.12 | K2: 1897.19 | L2: 2022.43 | M2: 45167 | N2: Active | O2: No
A3: PRD0002 | B3: Fastrack Jacket Orange | C3: Winter Wear | D3: Jacket | E3: Fastrack | F3: L | G3: Orange | H3: Rayon | I3: SUP008 | J3: 755.06 | K3: 1140.9 | L3: 1278.39 | M3: 45452 | N3: Active | O3: No
A4: PRD0003 | B4: Westside Straight Fit Charcoal | C4: Men Jeans | D4: Straight Fit | E4: Westside | F4: XXL | G4: Charcoal | H4: Chiffon | I4: SUP009 | J4: 1007.65 | K4: 1547.59 | L4: 1669.16 | M4: 45459 | N4: Active | O4: Yes
A5: PRD0004 | B5: Westside Bodycon Dress Green | C5: Women Dresses | D5: Bodycon Dress | E5: Westside | F5: XS | G5: Green | H5: Leather | I5: SUP010 | J5: 1144.59 | K5: 1663.91 | L5: 2062.86 | M5: 45323 | N5: Active | O5: No
A6: PRD0005 | B6: Woodland Digital Watch Brown | C6: Watches | D6: Digital Watch | E6: Woodland | F6: Free Size | G6: Brown | H6: Wool | I6: SUP064 | J6: 1806.03 | K6: 2408.53 | L6: 2991.64 | M6: 44615 | N6: Active | O6: No
A7: PRD0006 | B7: Liberty Braided Belt Red | C7: Belts | D7: Braided Belt | E7: Liberty | F7: Free Size | G7: Red | H7: Linen | I7: SUP063 | J7: 753.73 | K7: 1101.36 | L7: 1203.69 | M7: 45146 | N7: Active | O7: No
A8: PRD0007 | B8: Pepe Jeans Silk Saree Navy Blue | C8: Women Sarees | D8: Silk Saree | E8: Pepe Jeans | F8: S | G8: Navy Blue | H8: Viscose | I8: SUP009 | J8: 3236.57 | K8: 4477.9 | L8: 4780.42 | M8: 45216 | N8: Active | O8: No
A9: PRD0008 | B9: Aurelia Zip Wallet Grey | C9: Wallets | D9: Zip Wallet | E9: Aurelia | F9: Free Size | G9: Grey | H9: Nylon | I9: SUP016 | J9: 938.61 | K9: 1370.43 | L9: 1486.67 | M9: 45302 | N9: Active | O9: No
A10: PRD0009 | B10: W for Woman Cotton Saree Wine | C10: Women Sarees | D10: Cotton Saree | E10: W for Woman | F10: M | G10: Wine | H10: Cotton | I10: SUP012 | J10: 2340.46 | K10: 3184.6 | L10: 3855.7 | M10: 45691 | N10: Active | O10: No
A11: PRD0010 | B11: Killer Jeans Skinny Fit Wine | C11: Men Jeans | D11: Skinny Fit | E11: Killer Jeans | F11: L | G11: Wine | H11: Georgette | I11: SUP058 | J11: 1061.5 | K11: 1589.07 | L11: 1691.96 | M11: 45211 | N11: Active | O11: No
A12: PRD0011 | B12: Pepe Jeans Scarf Cream | C12: Accessories | D12: Scarf | E12: Pepe Jeans | F12: Free Size | G12: Cream | H12: Synthetic Blend | I12: SUP008 | J12: 414.5 | K12: 742.76 | L12: 799.07 | M12: 45591 | N12: Inactive | O12: No
A13: PRD0012 | B13: Aurelia Chinos Grey | C13: Men Trousers | D13: Chinos | E13: Aurelia | F13: M | G13: Grey | H13: Denim | I13: SUP011 | J13: 967.37 | K13: 1274.65 | L13: 1579.92 | M13: 45624 | N13: Inactive | O13: No
... A251: PRD0250 | B251: Pepe Jeans Digital Watch Charcoal | C251: Watches | D251: Digital Watch | E251: Pepe Jeans | F251: Free Size | G251: Charcoal | H251: Cotton | I251: SUP052 | J251: 3650.55 | K251: 4724.03 | L251: 5117.39 | M251: 44930 | N251: Active | O251: No

Sheet Stores
A1: Store_ID | B1: Store Name | C1: City | D1: State | E1: Region | F1: Store Type | G1: Opening Date | H1: Monthly Target | I1: Manager | J1: Status
A2: STR001 | B2: TrendMart Kollam Standard | C2: Kollam | D2: Kerala | E2: South Zone 1 | F2: Standard | G2: 44952 | H2: 2500000 | I2: Harini Reddy | J2: Active
A3: STR002 | B3: TrendMart Thrissur Standard | C3: Thrissur | D3: Kerala | E3: South Zone 1 | F3: Standard | G3: 42703 | H3: 1000000 | I3: Geetha Mishra | J3: Active
A4: STR003 | B4: TrendMart Tumakuru High Street | C4: Tumakuru | D4: Karnataka | E4: South Zone 2 | F4: High Street | G4: 44971 | H4: 2500000 | I4: Pranav Chandran | J4: Active
A5: STR004 | B5: TrendMart Kalaburagi Mall Kiosk | C5: Kalaburagi | D5: Karnataka | E5: South Zone 2 | F5: Mall Kiosk | G5: 42449 | H5: 800000 | I5: Chidambaram Balasubramaniam | J5: Active
A6: STR005 | B6: TrendMart Kochi High Street | C6: Kochi | D6: Kerala | E6: South Zone 1 | F6: High Street | G6: 44523 | H6: 2000000 | I6: Girish Gupta | J6: Active
A7: STR006 | B7: TrendMart Vellore Standard | C7: Vellore | D7: Tamil Nadu | E7: South Zone 1 | F7: Standard | G7: 44476 | H7: 2000000 | I7: Jyothi Kumar | J7: Active
A8: STR007 | B8: TrendMart Thoothukudi Mall Kiosk | C8: Thoothukudi | D8: Tamil Nadu | E8: South Zone 1 | F8: Mall Kiosk | G8: 45291 | H8: 1500000 | I8: Anusuya Venkatesan | J8: Active
A9: STR008 | B9: TrendMart Kochi Mall Kiosk | C9: Kochi | D9: Kerala | E9: South Zone 1 | F9: Mall Kiosk | G9: 43047 | H9: 1500000 | I9: Sangeeta Chettiar | J9: Active
A10: STR009 | B10: TrendMart Thrissur High Street | C10: Thrissur | D10: Kerala | E10: South Zone 1 | F10: High Street | G10: 42027 | H10: 2500000 | I10: Priya Prasad | J10: Active
A11: STR010 | B11: TrendMart Kochi Mall Kiosk | C11: Kochi | D11: Kerala | E11: South Zone 1 | F11: Mall Kiosk | G11: 42846 | H11: 2500000 | I11: Eshwari Raman | J11: Active
A12: STR011 | B12: TrendMart Tirupati Standard | C12: Tirupati | D12: Andhra Pradesh | E12: South Zone 3 | F12: Standard | G12: 43075 | H12: 2000000 | I12: Yogesh Murthy | J12: Active
A13: STR012 | B13: TrendMart Vijayawada Mall Kiosk | C13: Vijayawada | D13: Andhra Pradesh | E13: South Zone 3 | F13: Mall Kiosk | G13: 45215 | H13: 2000000 | I13: Bala Yadav | J13: Active
... A121: STR120 | B121: TrendMart Karimnagar Standard | C121: Karimnagar | D121: Telangana | E121: South Zone 2 | F121: Standard | G121: 43756 | H121: 1500000 | I121: Anusuya Subramaniam | J121: Active

Sheet Employees
A1: Employee_ID | B1: Employee Name | C1: Department | D1: Designation | E1: Salary | F1: Joining Date | G1: Store_ID | H1: Performance Rating | I1: Employment Status
A2: EMP0001 | B2: Charulatha Kumar | C2: Sales | D2: Sales Executive | E2: 16400 | F2: 44241 | G2: STR106 | H2: 4.6 | I2: On Leave
A3: EMP0002 | B3: Girish Sundaram | C3: Sales | D3: Sales Executive | E3: 20000 | F3: 45504 | G3: STR081 | H3: 4.9 | I3: Active
A4: EMP0003 | B4: Muthu Chettiar | C4: Management | D4: Store Manager | E4: 54000 | F4: 44881 | G4: STR118 | H4: 2.2 | I4: Active
A5: EMP0004 | B5: Naresh Reddy | C5: Cashier | D5: Cashier | E5: 20200 | F5: 45221 | G5: STR070 | H5: 2.4 | I5: Active
A6: EMP0005 | B6: Srinivas Srinivasan | C6: Customer Service | D6: Floor Assistant | E6: 14700 | F6: 43697 | G6: STR089 | H6: 3.9 | I6: Active
A7: EMP0006 | B7: Sanjay Reddy | C7: Cashier | D7: Senior Cashier | E7: 19100 | F7: 42719 | G7: STR068 | H7: 4.1 | I7: Active
A8: EMP0007 | B8: Indira Natarajan | C8: Housekeeping | D8: Housekeeping Staff | E8: 13800 | F8: 43742 | G8: STR073 | H8: 4.6 | I8: On Leave
A9: EMP0008 | B9: Deepak Kamath | C9: Sales | D9: Senior Sales Associate | E9: 19000 | F9: 45360 | G9: STR099 | H9: 4.9 | I9: Active
A10: EMP0009 | B10: Vinod Hegde | C10: Sales | D10: Sales Executive | E10: 25000 | F10: 42420 | G10: STR059 | H10: 3.5 | I10: Active
A11: EMP0010 | B11: Tejaswini Mudaliar | C11: Customer Service | D11: Floor Assistant | E11: 17600 | F11: 44179 | G11: STR011 | H11: 3.8 | I11: Active
A12: EMP0011 | B12: Gayathri Murthy | C12: Customer Service | D12: Customer Service Executive | E12: 15500 | F12: 42595 | G12: STR084 | H12: 3 | I12: Active
A13: EMP0012 | B13: Muthu Krishnan | C13: Cashier | D13: Cashier | E13: 14900 | F13: 43100 | G13: STR021 | H13: 4 | I13: Active
... A301: EMP0300 | B301: Ajay Iyengar | C301: Inventory | D301: Stock Associate | E301: 23200 | F301: 42455 | G301: STR107 | H301: 4 | I301: Active

Sheet Suppliers
A1: Supplier_ID | B1: Supplier Name | C1: Contact Person | D1: Phone | E1: Email | F1: City | G1: State | H1: Lead Time | I1: Supplier Rating | J1: Status
A2: SUP001 | B2: Cauvery Garments | C2: Jagan Mudaliar | D2: 9819600133 | E2: jagan.mudaliar1@hotmail.com | F2: Mangaluru | G2: Karnataka | H2: 26 | I2: 2.8 | J2: Active
A3: SUP002 | B3: Kaveri Textiles | C3: Deepthi Balasubramaniam | D3: 9265423511 | E3: deepthi.balasubramaniam2@rediffmail.com | F3: Shivamogga | G3: Karnataka | H3: 21 | I3: 3.2 | J3: Active
A4: SUP003 | B4: Royal Exports | C4: Bharathi Nair | D4: 9849593103 | E4: bharathi.nair3@outlook.com | F4: Kurnool | G4: Andhra Pradesh | H4: 6 | I4: 4.9 | J4: Active
A5: SUP004 | B5: Om Apparels | C5: Anusuya Gounder | D5: 9341928327 | E5: anusuya.gounder4@rediffmail.com | F5: Tirupati | G5: Andhra Pradesh | H5: 29 | I5: 3.4 | J5: Active
A6: SUP005 | B6: Prime Creations | C6: Raghu Menon | D6: 9395376724 | E6: raghu.menon5@yahoo.com | F6: Bengaluru | G6: Karnataka | H6: 28 | I6: 3.3 | J6: Active
A7: SUP006 | B7: Metro Creations | C7: Haritha Mishra | D7: 9710122691 | E7: haritha.mishra6@rediffmail.com | F7: Guntur | G7: Andhra Pradesh | H7: 10 | I7: 5 | J7: Active
A8: SUP007 | B8: Silver Industries | C8: Bindu Naicker | D8: 9845146270 | E8: bindu.naicker7@outlook.com | F8: Kannur | G8: Kerala | H8: 3 | I8: 4.2 | J8: Active
A9: SUP008 | B9: Grand Fabrics | C9: Vani Pandian | D9: 9880957015 | E9: vani.pandian8@outlook.com | F9: Kollam | G9: Kerala | H9: 9 | I9: 2.9 | J9: Active
A10: SUP009 | B10: Metro Textiles | C10: Praveen Reddy | D10: 9782489638 | E10: praveen.reddy9@yahoo.com | F10: Visakhapatnam | G10: Andhra Pradesh | H10: 27 | I10: 3.8 | J10: Active
A11: SUP010 | B11: Ashoka Fashions | C11: Bala Ramachandran | D11: 9098393010 | E11: bala.ramachandran10@yahoo.com | F11: Thrissur | G11: Kerala | H11: 6 | I11: 3.1 | J11: Inactive
A12: SUP011 | B12: Om Textiles | C12: Radha Gupta | D12: 9997376311 | E12: radha.gupta11@rediffmail.com | F12: Belagavi | G12: Karnataka | H12: 24 | I12: 3.7 | J12: Active
A13: SUP012 | B13: Golden Mills | C13: Anand Rao | D13: 9333872624 | E13: anand.rao12@rediffmail.com | F13: Erode | G13: Tamil Nadu | H13: 26 | I13: 3.3 | J13: Active
... A91: SUP090 | B91: Classic Exports | C91: Meena Krishnan | D91: 9765277584 | E91: meena.krishnan90@gmail.com | F91: Hyderabad | G91: Telangana | H91: 28 | I91: 3.4 | J91: Active

Sheet Data_Cleaning_Log
A1: Sheet | B1: Cleaning Action | C1: Rows Affected
A2: Sales_Transactions | B2: Mixed Date Formats standardized to datetime | C2: 6
A3: Sales_Transactions | B3: Duplicate Invoice Numbers made unique (suffixed) | C3: 5
A4: Sales_Transactions | B4: Blank Customer_ID filled as CUST_UNKNOWN | C4: 6
A5: Sales_Transactions | B5: Blank Product_ID filled as PRD_UNKNOWN | C5: 5
A6: Sales_Transactions | B6: Blank Employee_ID filled as EMP_UNKNOWN | C6: 5
A7: Sales_Transactions | B7: Payment Mode spacing/casing standardized | C7: 8
A8: Sales_Transactions | B8: Return Status typos standardized | C8: 4
A9: Sales_Transactions | B9: Quantity=0 with zero sales amount flagged Void/Cancelled | C9: 52
A10: Sales_Transactions | B10: Quantity=0 with positive sales amount - quantity imputed | C10: 5
A11: Sales_Transactions | B11: Negative Profit transactions flagged (kept - genuine margin issue) | C11: 179
A12: Customers | B12: Leading/trailing spaces in Name trimmed | C12: 5
A13: Customers | B13: Mixed Gender values standardized (Male/Female) | C13: 5
... A23: Employees | B23: Status typos standardized | C23: 2
